[2023-01-23T10:48:36.056+0000] {processor.py:153} INFO - Started process (PID=72) to work on /home/airflow/.local/lib/python3.7/site-packages/airflow/example_dags/example_task_group_decorator.py
[2023-01-23T10:48:36.059+0000] {processor.py:743} INFO - Processing file /home/airflow/.local/lib/python3.7/site-packages/airflow/example_dags/example_task_group_decorator.py for tasks to queue
[2023-01-23T10:48:36.061+0000] {logging_mixin.py:137} INFO - [2023-01-23T10:48:36.060+0000] {dagbag.py:538} INFO - Filling up the DagBag from /home/airflow/.local/lib/python3.7/site-packages/airflow/example_dags/example_task_group_decorator.py
[2023-01-23T10:48:36.145+0000] {processor.py:753} INFO - DAG(s) dict_keys(['example_task_group_decorator']) retrieved from /home/airflow/.local/lib/python3.7/site-packages/airflow/example_dags/example_task_group_decorator.py
[2023-01-23T10:48:36.259+0000] {logging_mixin.py:137} INFO - [2023-01-23T10:48:36.259+0000] {dag.py:2676} INFO - Sync 1 DAGs
[2023-01-23T10:48:36.304+0000] {logging_mixin.py:137} INFO - [2023-01-23T10:48:36.304+0000] {dag.py:3427} INFO - Setting next_dagrun for example_task_group_decorator to 2023-01-22T10:48:36.303718+00:00, run_after=2023-01-23T10:48:36.303718+00:00
[2023-01-23T10:48:36.332+0000] {processor.py:175} INFO - Processing /home/airflow/.local/lib/python3.7/site-packages/airflow/example_dags/example_task_group_decorator.py took 0.283 seconds
[2023-01-23T10:49:06.986+0000] {processor.py:153} INFO - Started process (PID=134) to work on /home/airflow/.local/lib/python3.7/site-packages/airflow/example_dags/example_task_group_decorator.py
[2023-01-23T10:49:06.994+0000] {processor.py:743} INFO - Processing file /home/airflow/.local/lib/python3.7/site-packages/airflow/example_dags/example_task_group_decorator.py for tasks to queue
[2023-01-23T10:49:07.001+0000] {logging_mixin.py:137} INFO - [2023-01-23T10:49:07.000+0000] {dagbag.py:538} INFO - Filling up the DagBag from /home/airflow/.local/lib/python3.7/site-packages/airflow/example_dags/example_task_group_decorator.py
[2023-01-23T10:49:07.278+0000] {processor.py:753} INFO - DAG(s) dict_keys(['example_task_group_decorator']) retrieved from /home/airflow/.local/lib/python3.7/site-packages/airflow/example_dags/example_task_group_decorator.py
[2023-01-23T10:49:07.601+0000] {logging_mixin.py:137} INFO - [2023-01-23T10:49:07.601+0000] {dag.py:2676} INFO - Sync 1 DAGs
[2023-01-23T10:49:07.669+0000] {logging_mixin.py:137} INFO - [2023-01-23T10:49:07.669+0000] {dag.py:3427} INFO - Setting next_dagrun for example_task_group_decorator to 2023-01-22T10:49:07.668352+00:00, run_after=2023-01-23T10:49:07.668352+00:00
[2023-01-23T10:49:07.725+0000] {processor.py:175} INFO - Processing /home/airflow/.local/lib/python3.7/site-packages/airflow/example_dags/example_task_group_decorator.py took 0.749 seconds
[2023-01-23T10:49:38.362+0000] {processor.py:153} INFO - Started process (PID=196) to work on /home/airflow/.local/lib/python3.7/site-packages/airflow/example_dags/example_task_group_decorator.py
[2023-01-23T10:49:38.365+0000] {processor.py:743} INFO - Processing file /home/airflow/.local/lib/python3.7/site-packages/airflow/example_dags/example_task_group_decorator.py for tasks to queue
[2023-01-23T10:49:38.366+0000] {logging_mixin.py:137} INFO - [2023-01-23T10:49:38.366+0000] {dagbag.py:538} INFO - Filling up the DagBag from /home/airflow/.local/lib/python3.7/site-packages/airflow/example_dags/example_task_group_decorator.py
[2023-01-23T10:49:38.397+0000] {processor.py:753} INFO - DAG(s) dict_keys(['example_task_group_decorator']) retrieved from /home/airflow/.local/lib/python3.7/site-packages/airflow/example_dags/example_task_group_decorator.py
[2023-01-23T10:49:38.443+0000] {logging_mixin.py:137} INFO - [2023-01-23T10:49:38.443+0000] {dag.py:2676} INFO - Sync 1 DAGs
[2023-01-23T10:49:38.470+0000] {logging_mixin.py:137} INFO - [2023-01-23T10:49:38.470+0000] {dag.py:3427} INFO - Setting next_dagrun for example_task_group_decorator to 2023-01-22T10:49:38.470211+00:00, run_after=2023-01-23T10:49:38.470211+00:00
[2023-01-23T10:49:38.488+0000] {processor.py:175} INFO - Processing /home/airflow/.local/lib/python3.7/site-packages/airflow/example_dags/example_task_group_decorator.py took 0.131 seconds
[2023-01-23T10:50:23.657+0000] {processor.py:153} INFO - Started process (PID=269) to work on /home/airflow/.local/lib/python3.7/site-packages/airflow/example_dags/example_task_group_decorator.py
[2023-01-23T10:50:23.677+0000] {processor.py:743} INFO - Processing file /home/airflow/.local/lib/python3.7/site-packages/airflow/example_dags/example_task_group_decorator.py for tasks to queue
[2023-01-23T10:50:23.689+0000] {logging_mixin.py:137} INFO - [2023-01-23T10:50:23.687+0000] {dagbag.py:538} INFO - Filling up the DagBag from /home/airflow/.local/lib/python3.7/site-packages/airflow/example_dags/example_task_group_decorator.py
[2023-01-23T10:50:24.052+0000] {processor.py:753} INFO - DAG(s) dict_keys(['example_task_group_decorator']) retrieved from /home/airflow/.local/lib/python3.7/site-packages/airflow/example_dags/example_task_group_decorator.py
[2023-01-23T10:50:28.598+0000] {logging_mixin.py:137} INFO - [2023-01-23T10:50:28.597+0000] {process_utils.py:256} INFO - Waiting up to 5 seconds for processes to exit...
[2023-01-23T10:50:28.615+0000] {processor.py:178} ERROR - Got an exception! Propagating...
Traceback (most recent call last):
  File "/home/airflow/.local/lib/python3.7/site-packages/airflow/utils/session.py", line 35, in create_session
    yield session
  File "/home/airflow/.local/lib/python3.7/site-packages/airflow/utils/session.py", line 75, in wrapper
    return func(*args, session=session, **kwargs)
  File "/home/airflow/.local/lib/python3.7/site-packages/airflow/dag_processing/processor.py", line 768, in process_file
    dagbag.sync_to_db(processor_subdir=self._dag_directory, session=session)
  File "/home/airflow/.local/lib/python3.7/site-packages/airflow/utils/session.py", line 72, in wrapper
    return func(*args, **kwargs)
  File "/home/airflow/.local/lib/python3.7/site-packages/airflow/models/dagbag.py", line 645, in sync_to_db
    for attempt in run_with_db_retries(logger=self.log):
  File "/home/airflow/.local/lib/python3.7/site-packages/tenacity/__init__.py", line 384, in __iter__
    do = self.iter(retry_state=retry_state)
  File "/home/airflow/.local/lib/python3.7/site-packages/tenacity/__init__.py", line 351, in iter
    return fut.result()
  File "/usr/local/lib/python3.7/concurrent/futures/_base.py", line 428, in result
    return self.__get_result()
  File "/usr/local/lib/python3.7/concurrent/futures/_base.py", line 384, in __get_result
    raise self._exception
  File "/home/airflow/.local/lib/python3.7/site-packages/airflow/models/dagbag.py", line 657, in sync_to_db
    serialize_errors.extend(_serialize_dag_capturing_errors(dag, session))
  File "/home/airflow/.local/lib/python3.7/site-packages/airflow/models/dagbag.py", line 631, in _serialize_dag_capturing_errors
    session=session,
  File "/home/airflow/.local/lib/python3.7/site-packages/airflow/utils/session.py", line 72, in wrapper
    return func(*args, **kwargs)
  File "/home/airflow/.local/lib/python3.7/site-packages/airflow/models/serialized_dag.py", line 159, in write_dag
    session.query(cls.dag_hash, cls.processor_subdir).filter(cls.dag_id == dag.dag_id).first()
  File "/home/airflow/.local/lib/python3.7/site-packages/sqlalchemy/orm/query.py", line 2823, in first
    return self.limit(1)._iter().first()
  File "/home/airflow/.local/lib/python3.7/site-packages/sqlalchemy/orm/query.py", line 2918, in _iter
    execution_options={"_sa_orm_load_options": self.load_options},
  File "/home/airflow/.local/lib/python3.7/site-packages/sqlalchemy/orm/session.py", line 1723, in execute
    result,
  File "/home/airflow/.local/lib/python3.7/site-packages/sqlalchemy/orm/context.py", line 335, in orm_setup_cursor_result
    "_sa_orm_load_options", QueryContext.default_load_options
  File "/home/airflow/.local/lib/python3.7/site-packages/airflow/dag_processing/manager.py", line 468, in _exit_gracefully
    self.end()
  File "/home/airflow/.local/lib/python3.7/site-packages/airflow/dag_processing/manager.py", line 1186, in end
    kill_child_processes_by_pids(pids_to_kill)
  File "/home/airflow/.local/lib/python3.7/site-packages/airflow/utils/process_utils.py", line 256, in kill_child_processes_by_pids
    log.info("Waiting up to %s seconds for processes to exit...", timeout)
  File "/usr/local/lib/python3.7/logging/__init__.py", line 1378, in info
    self._log(INFO, msg, args, **kwargs)
  File "/usr/local/lib/python3.7/logging/__init__.py", line 1514, in _log
    self.handle(record)
  File "/usr/local/lib/python3.7/logging/__init__.py", line 1524, in handle
    self.callHandlers(record)
  File "/usr/local/lib/python3.7/logging/__init__.py", line 1586, in callHandlers
    hdlr.handle(record)
  File "/usr/local/lib/python3.7/logging/__init__.py", line 894, in handle
    self.emit(record)
  File "/usr/local/lib/python3.7/logging/__init__.py", line 1025, in emit
    msg = self.format(record)
  File "/usr/local/lib/python3.7/logging/__init__.py", line 869, in format
    return fmt.format(record)
  File "/usr/local/lib/python3.7/logging/__init__.py", line 608, in format
    record.message = record.getMessage()
  File "/usr/local/lib/python3.7/logging/__init__.py", line 367, in getMessage
    msg = str(self.msg)
  File "/home/airflow/.local/lib/python3.7/site-packages/airflow/dag_processing/manager.py", line 470, in _exit_gracefully
    sys.exit(os.EX_OK)
SystemExit: 0

During handling of the above exception, another exception occurred:

Traceback (most recent call last):
  File "/home/airflow/.local/lib/python3.7/site-packages/sqlalchemy/engine/base.py", line 1057, in _rollback_impl
    self.engine.dialect.do_rollback(self.connection)
  File "/home/airflow/.local/lib/python3.7/site-packages/sqlalchemy/engine/default.py", line 683, in do_rollback
    dbapi_connection.rollback()
psycopg2.OperationalError: server closed the connection unexpectedly
	This probably means the server terminated abnormally
	before or while processing the request.


The above exception was the direct cause of the following exception:

Traceback (most recent call last):
  File "/home/airflow/.local/lib/python3.7/site-packages/airflow/dag_processing/processor.py", line 174, in _run_file_processor
    _handle_dag_file_processing()
  File "/home/airflow/.local/lib/python3.7/site-packages/airflow/dag_processing/processor.py", line 158, in _handle_dag_file_processing
    callback_requests=callback_requests,
  File "/home/airflow/.local/lib/python3.7/site-packages/airflow/utils/session.py", line 75, in wrapper
    return func(*args, session=session, **kwargs)
  File "/usr/local/lib/python3.7/contextlib.py", line 130, in __exit__
    self.gen.throw(type, value, traceback)
  File "/home/airflow/.local/lib/python3.7/site-packages/airflow/utils/session.py", line 41, in create_session
    session.close()
  File "/home/airflow/.local/lib/python3.7/site-packages/sqlalchemy/orm/session.py", line 1811, in close
    self._close_impl(invalidate=False)
  File "/home/airflow/.local/lib/python3.7/site-packages/sqlalchemy/orm/session.py", line 1853, in _close_impl
    transaction.close(invalidate)
  File "/home/airflow/.local/lib/python3.7/site-packages/sqlalchemy/orm/session.py", line 923, in close
    transaction.close()
  File "/home/airflow/.local/lib/python3.7/site-packages/sqlalchemy/engine/base.py", line 2416, in close
    self._do_close()
  File "/home/airflow/.local/lib/python3.7/site-packages/sqlalchemy/engine/base.py", line 2639, in _do_close
    self._close_impl()
  File "/home/airflow/.local/lib/python3.7/site-packages/sqlalchemy/engine/base.py", line 2625, in _close_impl
    self._connection_rollback_impl()
  File "/home/airflow/.local/lib/python3.7/site-packages/sqlalchemy/engine/base.py", line 2617, in _connection_rollback_impl
    self.connection._rollback_impl()
  File "/home/airflow/.local/lib/python3.7/site-packages/sqlalchemy/engine/base.py", line 1059, in _rollback_impl
    self._handle_dbapi_exception(e, None, None, None, None)
  File "/home/airflow/.local/lib/python3.7/site-packages/sqlalchemy/engine/base.py", line 2125, in _handle_dbapi_exception
    sqlalchemy_exception, with_traceback=exc_info[2], from_=e
  File "/home/airflow/.local/lib/python3.7/site-packages/sqlalchemy/util/compat.py", line 210, in raise_
    raise exception
  File "/home/airflow/.local/lib/python3.7/site-packages/sqlalchemy/engine/base.py", line 1057, in _rollback_impl
    self.engine.dialect.do_rollback(self.connection)
  File "/home/airflow/.local/lib/python3.7/site-packages/sqlalchemy/engine/default.py", line 683, in do_rollback
    dbapi_connection.rollback()
sqlalchemy.exc.OperationalError: (psycopg2.OperationalError) server closed the connection unexpectedly
	This probably means the server terminated abnormally
	before or while processing the request.

(Background on this error at: https://sqlalche.me/e/14/e3q8)
